异常是程序在执行期间产生的问题。C++ 异常是指在程序运行时发生的特殊情况，比如尝试除以零的操作。

异常提供了一种转移程序控制权的方式。C++ 异常处理涉及到三个关键字：**try、catch、throw**。

- **throw:** 当问题出现时，程序会抛出一个异常。这是通过使用 **throw** 关键字来完成的。
- **catch:** 在您想要处理问题的地方，通过异常处理程序捕获异常。**catch** 关键字用于捕获异常。
- **try:** **try** 块中的代码标识将被激活的特定异常。它后面通常跟着一个或多个 catch 块。

如果有一个块抛出一个异常，捕获异常的方法会使用 **try** 和 **catch** 关键字。try 块中放置可能抛出异常的代码，try 块中的代码被称为保护代码。使用 try/catch 语句的语法如下所示：

``` cpp
try
{
   // 保护代码
}catch( ExceptionName e1 )
{
   // catch 块
}catch( ExceptionName e2 )
{
   // catch 块
}catch( ExceptionName eN )
{
   // catch 块
}
```

如果 **try** 块在不同的情境下会抛出不同的异常，这个时候**可以尝试罗列多个 catch 语句**，用于捕获不同类型的异常。

# 抛出异常

您可以使用 **throw** 语句在代码块中的任何地方抛出异常。throw 语句的操作数可以是任意的表达式，表达式的结果的类型决定了抛出的异常的类型。

以下是尝试除以零时抛出异常的实例：

``` cpp
double division(int a, int b)
{
   if( b == 0 )
   {
      throw "Division by zero condition!";
   }
   return (a/b);
}
```

# 捕获异常

**catch** 块跟在 **try** 块后面，用于捕获异常。您可以指定想要捕捉的异常类型，这是由 catch 关键字后的括号内的异常声明决定的。

``` cpp
try
{
   // 保护代码
}catch( ExceptionName e )
{
  // 处理 ExceptionName 异常的代码
}
```

上面的代码会捕获一个类型为 **ExceptionName** 的异常。如果您想让 catch 块能够处理 try 块抛出的任何类型的异常，则必须在异常声明的括号内使用省略号 ...，如下所示：

``` cpp
try
{
   // 保护代码
}catch(...)
{
  // 能处理任何异常的代码
}
```

下面是一个实例，抛出一个除以零的异常，并在 catch 块中捕获该异常。

``` cpp
#include <iostream>
using namespace std;
 
double division(int a, int b)
{
   if( b == 0 )
   {
      throw "Division by zero condition!";
   }
   return (a/b);
}
 
int main ()
{
   int x = 50;
   int y = 0;
   double z = 0;
 
   try {
     z = division(x, y);
     cout << z << endl;
   }catch (const char* msg) {
     cerr << msg << endl;
   }
 
   return 0;
}
```

由于我们抛出了一个类型为 **const char\*** 的异常，因此，当捕获该异常时，我们必须在 catch 块中使用 const char*。当上面的代码被编译和执行时，它会产生下列结果：

``` cpp
Division by zero condition!
```

# C++ 标准的异常

C++ 提供了一系列标准的异常，定义在 **<exception>** 中，我们可以在程序中使用这些标准的异常。它们是以父子类层次结构组织起来的，如下所示：

std::bad_alloc   std::bad_cast   std::bad_typeid    std::bad_exception   std::logic_error  std::runtime_error继承自**std::exception**

std::domain_error  std::invalid_argument   std::length_error  std::out_of_range  继承自std::logic_error

std::overflw_error  std:rang_error  std::underflow_error 继承自std::runtime_error

下表是对上面层次结构中出现的每个异常的说明：

| 异常                   | 描述                                                         |
| :--------------------- | :----------------------------------------------------------- |
| **std::exception**     | 该异常是所有标准 C++ 异常的父类。                            |
| std::bad_alloc         | 该异常可以通过 **new** 抛出。                                |
| std::bad_cast          | 该异常可以通过 **dynamic_cast** 抛出。                       |
| std::bad_exception     | 这在处理 C++ 程序中无法预期的异常时非常有用。                |
| std::bad_typeid        | 该异常可以通过 **typeid** 抛出。                             |
| **std::logic_error**   | 理论上可以通过读取代码来检测到的异常。                       |
| std::domain_error      | 当使用了一个无效的数学域时，会抛出该异常。                   |
| std::invalid_argument  | 当使用了无效的参数时，会抛出该异常。                         |
| std::length_error      | 当创建了太长的 std::string 时，会抛出该异常。                |
| std::out_of_range      | 该异常可以通过方法抛出，例如 std::vector 和 std::bitset<>::operator[]()。 |
| **std::runtime_error** | 理论上不可以通过读取代码来检测到的异常。                     |
| std::overflow_error    | 当发生数学上溢时，会抛出该异常。                             |
| std::range_error       | 当尝试存储超出范围的值时，会抛出该异常。                     |
| std::underflow_error   | 当发生数学下溢时，会抛出该异常。                             |

# 定义新的异常

您可以通过继承和重载 **exception** 类来定义新的异常。下面的实例演示了如何使用 std::exception 类来实现自己的异常：

``` cpp
#include <iostream>
#include <exception>
using namespace std;
 
struct MyException : public exception
{
  const char * what () const throw ()
  {
    return "C++ Exception";
  }
};
 
int main()
{
  try
  {
    throw MyException();
  }
  catch(MyException& e)
  {
    std::cout << "MyException caught" << std::endl;
    std::cout << e.what() << std::endl;
  }
  catch(std::exception& e)
  {
    //其他的错误
  }
}
```

运行结果

``` cpp
MyException caught
C++ Exception
```

在这里，**what()** 是异常类提供的一个公共方法，它已被所有子异常类重载。这将返回异常产生的原因。


# throw std::runtime_error 实践

在 C++ 中，throw std::runtime_error 和 std::cout 打印错误的区别主要体现在错误处理机制和程序控制流上

1. 错误处理机制
   * throw std::runtime_error：属于异常处理机制，通过抛出异常对象强制中断当前执行流，需要调用者用 try-catch 捕获处理
   * std::cout：仅将错误信息输出到标准输出流，程序控制流不会中断（建议错误输出应使用 std::cerr 到标准错误流更规范）
2. 典型使用场景

```cpp
// 异常处理示例（如你上下文代码所示）
void addWatch(const std::string& filename) {
    if (access(...) == -1) {
        throw std::runtime_error(...); // 强制调用方必须处理这个错误
    }
}

// 控制台输出示例（通常用于非致命错误）
void handleFileModify(int wd) {
    try { ... } 
    catch (const std::exception& e) {
        std::cerr << "Error: " << e.what(); // 仅记录错误，程序继续运行
    }
}
```

3. 关键差异点
   
   | 特性 | throw std::runtime_error | std::cout |
   | --- | --- | --- |
   |控制流程|必须被捕获处理，否则程序终止|仅输出错误信息，程序继续运行|
   |错误信息携带|	可携带结构化异常对象（含 what() 信息）|	仅输出字符串|
   |跨函数传播能力	|可通过调用栈向上层传播	|仅限于当前作用域|
   |性能影响	|较高（涉及栈展开）	|较低|
   |代码健壮性要求	|需要严格的异常安全保证	|对代码结构要求较低|

4. 选择建议
   * 对于需要强制中断程序执行流的错误，如文件访问错误，应使用 throw std::runtime_error
   * 对于非致命错误，如日志记录，应使用 std::cout 或 std::cerr，以保持程序的正常运行
  
5. 使用 throw 的场景
   
   **需要强制调用方处理的错误**

    异常处理机制的特点：异常抛出方不负责捕获，而是由调用方负责处理。

示例代码，监控文件变化：
```cpp
void addWatch(const std::string& filename) {
    if (access(...) == -1) {
        throw std::runtime_error(...); // 由调用者处理
    }
    //...
}
```
关键逻辑：
* 职责分离：addWatch 作为被调用函数，职责是发现问题并抛出异常（错误产生方）
* 调用方责任：调用 addWatch 的代码需要自己用 try-catch 处理（错误处理方）

调用示例：
```cpp
int main() {
    FileWatcher watcher(...);
    try {
        watcher.addWatch("important_config.json"); // 可能抛出异常的调用
    } 
    catch (const std::runtime_error& e) {
        std::cerr << "监控初始化失败: " << e.what();
        return EXIT_FAILURE; // 优雅地处理错误
    }
    // 正常业务逻辑...
}
```

需要注意的是：std::cerr << "监控初始化失败: " << e.what();才是真正打印错误的地方，而不是throw std::runtime_error(...);

为什么这样设计？
* 错误传播：当底层函数（如 addWatch）无法合理处理错误时，应该将错误传递给上层
* 强制处理：如果不处理异常，程序会终止（避免隐藏错误）
* 上下文感知：只有调用方知道在出错时应该进行重试、回滚还是终止

**最佳实践总结**

|场景	|处理方式|	示例|
| --- | --- | --- |
|关键错误（影响后续操作）	|throw 异常，调用方处理	|文件监控初始化失败|
|非关键错误（可局部恢复）|	本地捕获处理	|单个文件解析失败|
|程序无法继续运行的致命错误	|throw 异常 + 顶层捕获|	内存分配失败、关键资源获取失败|

6. C开发思路对比

C语言开发在错误处理设计上，返回错误码和异常机制确实都能达到目的，但它们在代码质量、安全性和使用场景上有本质区别。

* 错误码模式
```cpp
int addWatch(const std::string& filename, char** errorMsg) {
    if (access(...) == -1) {
        *errorMsg = "File not found";
        return -1; // 错误码
    }
    // ...
    return 0; // 成功
}

// 调用方代码
char* err = nullptr;
int ret = addWatch("config.json", &err);
if (ret != 0) {
    std::cerr << err; // 必须手动检查
    free(err);
}
```
* 异常模式
```cpp
void addWatch(const std::string& filename) {
    if (access(...) == -1) {
        throw std::runtime_error(...); // 自动传播错误
    }
    //...
}

// 调用方代码
try {
    addWatch("config.json"); // 干净的调用接口
} 
catch (const std::exception& e) {
    std::cerr << e.what(); // 集中处理
}
```
关键差异分析

|特性|	异常机制（try-catch）	|错误码模式|
| --- | --- | --- |
|错误传播	|自动跨多级调用栈传播（无需逐层传递）	|需手动逐层返回错误码|
|代码耦合度	|调用方与错误处理逻辑解耦	|调用方需立即处理错误码，耦合度高|
|资源泄漏风险	|栈展开自动调用析构函数，资源安全	|需手动管理资源释放（容易忘记）|
|构造函数错误处理	|唯一可靠方式（构造函数无返回值）|	无法直接处理构造函数错误|
|可读性	|业务逻辑与错误处理分离，代码更清晰	|大量 if (ret != 0) 干扰主逻辑|
|性能	|抛出异常时开销较大（但正常路径无额外消耗）	|无额外性能消耗（适合高频调用场景）|
|类型安全性	|可抛任意异常类型（继承自 std::exception）|	只能通过整数或字符串传递错误信息|
|多线程错误传递	|天然支持跨线程传播（如您代码中的 std::thread）	|需自行设计线程间错误传递机制|








